<robot name="AERO_arm" >
  <link
    name="base_link">
    <inertial>
      <origin
        xyz="0 0 0"
        rpy="0 0 0" />
      <mass
        value="0" />
      <inertia
        ixx="0"
        ixy="0"
        ixz="0"
        iyy="0"
        iyz="0"
        izz="0" />
    </inertial>
    <visual>
      <origin
        xyz="0 0 0"
        rpy="0 0 0" />
      <geometry>
        <mesh
          filename="package://AERO_arm/meshes/base_link.STL" />
      </geometry>
      <material
        name="">
        <color
          rgba="0.792156862745098 0.819607843137255 0.933333333333333 1" />
      </material>
    </visual>
    <collision>
      <origin
        xyz="0 0 0"
        rpy="0 0 0" />
      <geometry>
        <mesh
          filename="package://AERO_arm/meshes/base_link.STL" />
      </geometry>
    </collision>
  </link>
  <link
    name="Link1">
    <inertial>
      <origin
        xyz="0 0 0"
        rpy="0 0 0" />
      <mass
        value="0" />
      <inertia
        ixx="0"
        ixy="0"
        ixz="0"
        iyy="0"
        iyz="0"
        izz="0" />
    </inertial>
    <visual>
      <origin
        xyz="0 0 0"
        rpy="1.57 0 0" />
      <geometry>
        <mesh
          filename="package://AERO_arm/meshes/Link1.STL" />
      </geometry>
      <material
        name="">
        <color
          rgba="0.792156862745098 0.819607843137255 0.933333333333333 1" />
      </material>
    </visual>
    <collision>
      <origin
        xyz="0 0 0"
        rpy="1.57 0 0" />
      <geometry>
        <mesh
          filename="package://AERO_arm/meshes/Link1.STL" />
      </geometry>
    </collision>
  </link>
  <joint
    name="Joint1"
    type="continuous">
    <origin
      xyz="0 0 0"
      rpy="0 0 0" />
    <parent
      link="base_link" />
    <child
      link="Link1" />
    <axis
      xyz="0 0 -1" />
  </joint>
  <link
    name="Link2">
    <inertial>
      <origin
        xyz="0 0 0"
        rpy="0 0 0" />
      <mass
        value="0" />
      <inertia
        ixx="0"
        ixy="0"
        ixz="0"
        iyy="0"
        iyz="0"
        izz="0" />
    </inertial>
    <visual>
      <origin
        xyz=".205 0 0"
        rpy="3.14 0 0" />
      <geometry>
        <mesh
          filename="package://AERO_arm/meshes/Link2.STL" />
      </geometry>
      <material
        name="">
        <color
          rgba="0.792156862745098 0.819607843137255 0.933333333333333 1" />
      </material>
    </visual>
    <collision>
      <origin
        xyz=".205 0 0"
        rpy="3.14 0 0" />
      <geometry>
        <mesh
          filename="package://AERO_arm/meshes/Link2.STL" />
      </geometry>
    </collision>
  </link>
  <joint
    name="Joint2"
    type="continuous">
   <!-- <origin
      xyz="0 0 0.11875"
      rpy="0.0025506 -1.5708 0" /> -->
    <origin
      xyz="0 0 0.12"
      rpy="0.0 -1.5708 0" />
    <parent
      link="Link1" />
    <child
      link="Link2" />
    <axis
      xyz="0 0 -1" />
  </joint>
  <link
    name="Link3">
    <inertial>
<!--
      <origin
        xyz="0.01 -.04125 0"
        rpy="0.01 0 0" />
-->
     <origin
        xyz="0.00 0 0"
        rpy="0.00 0 0" />
      <mass
        value="0" />
      <inertia
        ixx="0"
        ixy="0"
        ixz="0"
        iyy="0"
        iyz="0"
        izz="0" />
    </inertial>
    <visual>
      <origin
        xyz="0 0 0"
        rpy="0 0 0" />
      <geometry>
        <mesh
          filename="package://AERO_arm/meshes/Link4_origin.STL" scale="0.001 0.001 0.001"/>
      </geometry>
      <material
        name="">
        <color
          rgba="0.792156862745098 0.819607843137255 0.933333333333333 1" />
      </material>
    </visual>
    <collision>
      <origin
        xyz="0 0 0"
        rpy="0 0 0" />
      <geometry>
        <mesh
          filename="package://AERO_arm/meshes/Link4_origin.STL" scale="0.001 0.001 0.001"/>
      </geometry>
    </collision>
  </link>
  <joint
    name="Joint3"
    type="continuous">
<!--
    <origin
      xyz="0.40806 -0.038517 0"
      rpy="-3.1416 -7.9134E-09 -0.28747" />
-->
    <origin
      xyz="0.41 0 0"
      rpy="-3.1416 0 -0.28747" />
    <parent
      link="Link2" />
    <child
      link="Link3" />
    <axis
      xyz="0 0 -1" />
  </joint>
  <link
    name="Link4">
    <inertial>
      <origin
        xyz="0 0 0"
        rpy="0 0 0" />
      <mass
        value="0" />
      <inertia
        ixx="0"
        ixy="0"
        ixz="0"
        iyy="0"
        iyz="0"
        izz="0" />
    </inertial>
    <visual>
      <origin
        xyz="0 0 0"
        rpy="0 0 0" />
      <geometry>
        <mesh
          filename="package://AERO_arm/meshes/origin_fixed.STL" scale="0.001 0.001 0.001"/>
      </geometry>
      <material
        name="">
        <color
          rgba="0.792156862745098 0.819607843137255 0.933333333333333 1" />
      </material>
    </visual>
    <collision>
      <origin
        xyz="0 0 0"
        rpy="0 0 0" />
      <geometry>
        <mesh
          filename="package://AERO_arm/meshes/origin_fixed.STL" scale="0.001 0.001 0.001"/>
      </geometry>
    </collision>
  </link>
  <joint
    name="Joint4"
    type="continuous">
<!--
    <origin
      xyz="0.12269 0.16673 0.011497"
      rpy="1.5708 0.064781 -0.63437" />
-->
   <origin
      xyz="0.2073 0.0 0.011497"
      rpy="0 -1.5708 0.0"/>

    <parent
      link="Link3" />
    <child
      link="Link4" />
    <axis
      xyz="0 0 1" />
  </joint>
  <link
    name="Link5">
    <inertial>
      <origin
        xyz="0 0 0"
        rpy="0 0 0" />
      <mass
        value="0" />
      <inertia
        ixx="0"
        ixy="0"
        ixz="0"
        iyy="0"
        iyz="0"
        izz="0" />
    </inertial>
    <visual>
      <origin
        xyz="0 0 0"
        rpy="0 0 0" />
      <geometry>
        <mesh
          filename="package://AERO_arm/meshes/origin_fixed.STL" scale="0.001 0.001 0.001"/>
      </geometry>
      <material
        name="">
        <color
          rgba="0.792156862745098 0.819607843137255 0.933333333333333 1" />
      </material>
    </visual>
    <collision>
      <origin
        xyz="0 0 0"
        rpy="0 0 0" />
      <geometry>
        <mesh
          filename="package://AERO_arm/meshes/origin_fixed.STL" scale="0.001 0.001 0.001"/>
      </geometry>
    </collision>
  </link>
  <joint
    name="Joint5"
    type="continuous">
<!--
    <origin
      xyz="0.030052 -0.016526 -0.065632"
      rpy="0.12154 -0.95472 -0.65131" />
-->
    <origin
      xyz="0.027925 -0.019554 -0.065738"
      rpy="0.12154 -0.95472 -0.65131" />

    <parent
      link="Link4" />
    <child
      link="Link5" />
    <axis
      xyz="0 0 1" />
  </joint>
  <link
    name="Gripper">
    <inertial>
      <origin
        xyz="0 0 0"
        rpy="0 0 0" />
      <mass
        value="0" />
      <inertia
        ixx="0"
        ixy="0"
        ixz="0"
        iyy="0"
        iyz="0"
        izz="0" />
    </inertial>
    <visual>
      <origin
        xyz="0 0 0"
        rpy="0 0 0" />
      <geometry>
        <mesh
          filename="package://AERO_arm/meshes/Gripper_origin.STL" scale="0.001 0.001 0.001"/>
      </geometry>
      <material
        name="">
        <color
          rgba="0.792156862745098 0.819607843137255 0.933333333333333 1" />
      </material>
    </visual>
    <collision>
      <origin
        xyz="0 0 0"
        rpy="0 0 0" />
      <geometry>
        <mesh
          filename="package://AERO_arm/meshes/Gripper_origin.STL" scale="0.001 0.001 0.001" />
      </geometry>
    </collision>
  </link>
  <joint
    name="Joint6"
    type="continuous">
<!--
    <origin
      xyz="-0.024641 -0.023854 -0.065632"
      rpy="-2.4455 0.72653 1.6683" />
    
--> 
    <origin
      xyz="0.027925 -0.019554 -0.065738"
      rpy="0.48869  2.1800 0" />
    <parent
      link="Link5" />
    <child
      link="Gripper" />
    <axis
      xyz="0 0 1" />
  </joint>
</robot>
