<?xml version="1.0" ?>
<!-- =================================================================================== -->
<!-- |    This document was autogenerated by xacro from AERO.urdf.xacro                | -->
<!-- |    EDITING THIS FILE BY HAND IS NOT RECOMMENDED                                 | -->
<!-- =================================================================================== -->
<!--
Copyright (c) 2012, Siddhant Ahuja (Sid), Ryan Gariepy
All rights reserved.

Redistribution and use in source and binary forms, with or without
modification, are permitted provided that the following conditions are met:
    * Redistributions of source code must retain the above copyright
      notice, this list of conditions and the following disclaimer.
    * Redistributions in binary form must reproduce the above copyright
      notice, this list of conditions and the following disclaimer in the
      documentation and/or other materials provided with the distribution.
    * Neither the name of Clearpath Robotics nor the
      names of its contributors may be used to endorse or promote products
      derived from this software without specific prior written permission.

THIS SOFTWARE IS PROVIDED BY THE COPYRIGHT HOLDERS AND CONTRIBUTORS "AS IS" AND
ANY EXPRESS OR IMPLIED WARRANTIES, INCLUDING, BUT NOT LIMITED TO, THE IMPLIED
WARRANTIES OF MERCHANTABILITY AND FITNESS FOR A PARTICULAR PURPOSE ARE
DISCLAIMED. IN NO EVENT SHALL THE COPYRIGHT HOLDERS BE LIABLE FOR ANY
DIRECT, INDIRECT, INCIDENTAL, SPECIAL, EXEMPLARY, OR CONSEQUENTIAL DAMAGES
(INCLUDING, BUT NOT LIMITED TO, PROCUREMENT OF SUBSTITUTE GOODS OR SERVICES;
LOSS OF USE, DATA, OR PROFITS; OR BUSINESS INTERRUPTION) HOWEVER CAUSED AND
ON ANY THEORY OF LIABILITY, WHETHER IN CONTRACT, STRICT LIABILITY, OR TORT
(INCLUDING NEGLIGENCE OR OTHERWISE) ARISING IN ANY WAY OUT OF THE USE OF THIS
SOFTWARE, EVEN IF ADVISED OF THE POSSIBILITY OF SUCH DAMAGE.

This program contains the description of the robot base model for the Clearpath 
Husky A200
-->
<robot name="AERO" xmlns:body="http://playerstage.sourceforge.net/gazebo/xmlschema/#body" xmlns:controller="http://playerstage.sourceforge.net/gazebo/xmlschema/#controller" xmlns:gazebo="http://playerstage.sourceforge.net/gazebo/xmlschema/#gz" xmlns:geom="http://playerstage.sourceforge.net/gazebo/xmlschema/#geom" xmlns:interface="http://playerstage.sourceforge.net/gazebo/xmlschema/#interface" xmlns:joint="http://playerstage.sourceforge.net/gazebo/xmlschema/#joint" xmlns:model="http://playerstage.sourceforge.net/gazebo/xmlschema/#model" xmlns:physics="http://playerstage.sourceforge.net/gazebo/xmlschema/#physics" xmlns:renderable="http://playerstage.sourceforge.net/gazebo/xmlschema/#renderable" xmlns:rendering="http://playerstage.sourceforge.net/gazebo/xmlschema/#rendering" xmlns:sensor="http://playerstage.sourceforge.net/gazebo/xmlschema/#sensor" xmlns:xacro="http://ros.org/wiki/xacro" xmlns:xi="http://www.w3.org/2001/XInclude">
  <!-- Included URDF/XACRO Files -->
  <material name="Black">
    <color rgba="0.0 0.0 0.0 1.0"/>
  </material>
  <material name="Blue">
    <color rgba="0.0 0.0 0.8 1.0"/>
  </material>
  <material name="Green">
    <color rgba="0.0 0.8 0.0 1.0"/>
  </material>
  <material name="Gray">
    <color rgba="0.7 0.7 0.7 1.0"/>
  </material>
  <material name="DarkGray">
    <color rgba="0.3 0.3 0.3 1.0"/>
  </material>
  <material name="Red">
    <color rgba="0.8 0.0 0.0 1.0"/>
  </material>
  <material name="White">
    <color rgba="1.0 1.0 1.0 1.0"/>
  </material>
  <material name="Yellow">
    <color rgba="0.8 0.8 0.0 1.0"/>
  </material>
  <!-- PROPERTY LIST -->
  <!--All units in m-kg-s-radians unit system -->
  <!-- Main Body-base-->
  <!-- Location of com : center of mass -->
  <!-- Size of the base-->
  <!--Weight of the base-->
  <!-- in kg-->
  <!--Inertial values for the base at center of mass, aligned with coordinate system. Units are kg*m^2-->
  <!-- BASE-FOOTPRINT -->
  <!-- base_footprint is a fictitious link(frame) that is on the ground right below base_link origin, navigation stack depends on this frame -->
  <link name="base_footprint">
    <inertial>
      <mass value="0.0001"/>
      <origin xyz="0 0 0"/>
      <inertia ixx="0.0001" ixy="0.0" ixz="0.0" iyy="0.0001" iyz="0.0" izz="0.0001"/>
    </inertial>
    <visual>
      <origin rpy="0 0 0" xyz="0 0 0"/>
      <geometry>
        <box size="0.001 0.001 0.001"/>
      </geometry>
    </visual>
  </link>
  <gazebo reference="base_footprint">
    <material>Gazebo/Green</material>
    <turnGravityOff>false</turnGravityOff>
  </gazebo>
  <joint name="base_footprint_joint" type="fixed">
    <origin rpy="0 0 0" xyz="0 0 0.13857492"/>
    <parent link="base_footprint"/>
    <child link="base_link"/>
  </joint>
  <!-- BASE-LINK -->
  <!--Actual body/chassis of the robot-->
  <link name="base_link">
    <inertial>
      <mass value="33.45489"/>
      <!--This is the pose of the inertial reference frame, relative to the link reference frame. The origin of the inertial reference frame needs to be at the center of gravity. The axes of the inertial reference frame do not need to be aligned with the principal axes of the inertia.-->
      <origin xyz="-0.08748 -0.00085 0.09947"/>
      <!--The 3x3 rotational inertia matrix. Because the rotational inertia matrix is symmetric, only 6 above-diagonal elements of this matrix are specified here, using the attributes ixx, ixy, ixz, iyy, iyz, izz.-->
      <inertia ixx="0.6021637" ixy="-0.02364198" ixz="-0.11972132" iyy="1.73859574" iyz="-0.00154437" izz="2.02955229"/>
    </inertial>
    <visual>
      <origin rpy="0 0 0" xyz="0 0 0.003175"/>
      <geometry>
        <mesh filename="package://husky_description/Media/models/base_link.stl"/>
      </geometry>
      <material name="Black"/>
    </visual>
    <collision>
      <origin rpy="0 0 0 " xyz="0 0 0.12492492"/>
      <geometry>
        <box size="1.0074 0.5709 0.2675"/>
        <!--making it slightly bigger in x and z direction-->
      </geometry>
    </collision>
  </link>
  <gazebo reference="base_link">
    <material>Gazebo/FlatBlack</material>
    <turnGravityOff>false</turnGravityOff>
  </gazebo>
  <!-- WHEEL macros -->
  <link name="back_left_wheel">
    <inertial>
      <mass value="2.63657"/>
      <origin xyz="0.0 0.0 0.00019"/>
      <inertia ixx="0.02466885" ixy="0.0" ixz="0.0" iyy="0.02466885" iyz="0.0" izz="0.04410576"/>
    </inertial>
    <visual>
      <origin rpy="-3.14159265359 0 0" xyz="0 0 0"/>
      <geometry>
        <mesh filename="package://husky_description/Media/models/wheel.stl"/>
      </geometry>
      <material name="DarkGray"/>
    </visual>
    <collision>
      <origin rpy="-3.14159265359 0 0" xyz="0 0 0"/>
      <geometry>
        <mesh filename="package://husky_description/Media/models/wheel.stl"/>
      </geometry>
    </collision>
  </link>
  <gazebo reference="back_left_wheel">
    <mu1 value="75.0"/>
    <mu2 value="1.5"/>
    <kp value="1000000.0"/>
    <kd value="1.0"/>
    <fdir1 value="1 0 0"/>
    <material>Gazebo/Grey</material>
    <turnGravityOff>false</turnGravityOff>
  </gazebo>
  <joint name="joint_back_left_wheel" type="continuous">
    <parent link="base_link"/>
    <child link="back_left_wheel"/>
    <origin rpy="0 0 0" xyz="-0.25600006 0.285475 0.03282508"/>
    <axis rpy="0 0 0" xyz="0 1 0"/>
    <limit effort="100" velocity="100"/>
    <joint_properties damping="0.0" friction="0.0"/>
  </joint>
  <transmission name="joint_back_left_wheel_trans" type="SimpleTransmission">
    <actuator name="joint_back_left_wheel_motor"/>
    <joint name="joint_back_left_wheel"/>
    <mechanicalReduction>1</mechanicalReduction>
    <motorTorqueConstant>1</motorTorqueConstant>
  </transmission>
  <link name="back_right_wheel">
    <inertial>
      <mass value="2.63657"/>
      <origin xyz="0.0 0.0 0.00019"/>
      <inertia ixx="0.02466885" ixy="0.0" ixz="0.0" iyy="0.02466885" iyz="0.0" izz="0.04410576"/>
    </inertial>
    <visual>
      <origin rpy="-3.14159265359 0 0" xyz="0 0 0"/>
      <geometry>
        <mesh filename="package://husky_description/Media/models/wheel.stl"/>
      </geometry>
      <material name="DarkGray"/>
    </visual>
    <collision>
      <origin rpy="-3.14159265359 0 0" xyz="0 0 0"/>
      <geometry>
        <mesh filename="package://husky_description/Media/models/wheel.stl"/>
      </geometry>
    </collision>
  </link>
  <gazebo reference="back_right_wheel">
    <mu1 value="75.0"/>
    <mu2 value="1.5"/>
    <kp value="1000000.0"/>
    <kd value="1.0"/>
    <fdir1 value="1 0 0"/>
    <material>Gazebo/Grey</material>
    <turnGravityOff>false</turnGravityOff>
  </gazebo>
  <joint name="joint_back_right_wheel" type="continuous">
    <parent link="base_link"/>
    <child link="back_right_wheel"/>
    <origin rpy="0 0 0" xyz="-0.25600006 -0.285475 0.03282508"/>
    <axis rpy="0 0 0" xyz="0 1 0"/>
    <limit effort="100" velocity="100"/>
    <joint_properties damping="0.0" friction="0.0"/>
  </joint>
  <transmission name="joint_back_right_wheel_trans" type="SimpleTransmission">
    <actuator name="joint_back_right_wheel_motor"/>
    <joint name="joint_back_right_wheel"/>
    <mechanicalReduction>1</mechanicalReduction>
    <motorTorqueConstant>1</motorTorqueConstant>
  </transmission>
  <link name="front_left_wheel">
    <inertial>
      <mass value="2.63657"/>
      <origin xyz="0.0 0.0 0.00019"/>
      <inertia ixx="0.02466885" ixy="0.0" ixz="0.0" iyy="0.02466885" iyz="0.0" izz="0.04410576"/>
    </inertial>
    <visual>
      <origin rpy="-3.14159265359 0 0" xyz="0 0 0"/>
      <geometry>
        <mesh filename="package://husky_description/Media/models/wheel.stl"/>
      </geometry>
      <material name="DarkGray"/>
    </visual>
    <collision>
      <origin rpy="-3.14159265359 0 0" xyz="0 0 0"/>
      <geometry>
        <mesh filename="package://husky_description/Media/models/wheel.stl"/>
      </geometry>
    </collision>
  </link>
  <gazebo reference="front_left_wheel">
    <mu1 value="75.0"/>
    <mu2 value="1.5"/>
    <kp value="1000000.0"/>
    <kd value="1.0"/>
    <fdir1 value="1 0 0"/>
    <material>Gazebo/Grey</material>
    <turnGravityOff>false</turnGravityOff>
  </gazebo>
  <joint name="joint_front_left_wheel" type="continuous">
    <parent link="base_link"/>
    <child link="front_left_wheel"/>
    <origin rpy="0 0 0" xyz="0.25600006 0.285475 0.03282508"/>
    <axis rpy="0 0 0" xyz="0 1 0"/>
    <limit effort="100" velocity="100"/>
    <joint_properties damping="0.0" friction="0.0"/>
  </joint>
  <transmission name="joint_front_left_wheel_trans" type="SimpleTransmission">
    <actuator name="joint_front_left_wheel_motor"/>
    <joint name="joint_front_left_wheel"/>
    <mechanicalReduction>1</mechanicalReduction>
    <motorTorqueConstant>1</motorTorqueConstant>
  </transmission>
  <link name="front_right_wheel">
    <inertial>
      <mass value="2.63657"/>
      <origin xyz="0.0 0.0 0.00019"/>
      <inertia ixx="0.02466885" ixy="0.0" ixz="0.0" iyy="0.02466885" iyz="0.0" izz="0.04410576"/>
    </inertial>
    <visual>
      <origin rpy="-3.14159265359 0 0" xyz="0 0 0"/>
      <geometry>
        <mesh filename="package://husky_description/Media/models/wheel.stl"/>
      </geometry>
      <material name="DarkGray"/>
    </visual>
    <collision>
      <origin rpy="-3.14159265359 0 0" xyz="0 0 0"/>
      <geometry>
        <mesh filename="package://husky_description/Media/models/wheel.stl"/>
      </geometry>
    </collision>
  </link>
  <gazebo reference="front_right_wheel">
    <mu1 value="75.0"/>
    <mu2 value="1.5"/>
    <kp value="1000000.0"/>
    <kd value="1.0"/>
    <fdir1 value="1 0 0"/>
    <material>Gazebo/Grey</material>
    <turnGravityOff>false</turnGravityOff>
  </gazebo>
  <joint name="joint_front_right_wheel" type="continuous">
    <parent link="base_link"/>
    <child link="front_right_wheel"/>
    <origin rpy="0 0 0" xyz="0.25600006 -0.285475 0.03282508"/>
    <axis rpy="0 0 0" xyz="0 1 0"/>
    <limit effort="100" velocity="100"/>
    <joint_properties damping="0.0" friction="0.0"/>
  </joint>
  <transmission name="joint_front_right_wheel_trans" type="SimpleTransmission">
    <actuator name="joint_front_right_wheel_motor"/>
    <joint name="joint_front_right_wheel"/>
    <mechanicalReduction>1</mechanicalReduction>
    <motorTorqueConstant>1</motorTorqueConstant>
  </transmission>
  <!-- DECORATIONS -->
  <!-- Top Plate -->
  <joint name="base_link_top_plate_joint" type="fixed">
    <origin rpy="0.0 0.0 0.0" xyz="0.0 0.0 0.005"/>
    <parent link="base_link"/>
    <child link="base_link_top_plate_part"/>
  </joint>
  <link name="base_link_top_plate_part">
    <inertial>
      <mass value="0.1"/>
      <origin xyz="0.0 0.0 0.0"/>
      <inertia ixx="0.01" ixy="0.0" ixz="0.0" iyy="0.01" iyz="0.0" izz="0.01"/>
    </inertial>
    <visual>
      <origin rpy="0 0 0" xyz="0 0 0"/>
      <geometry>
        <mesh filename="package://husky_description/Media/models/top_plate.stl"/>
      </geometry>
      <material name="Yellow"/>
    </visual>
    <collision>
      <origin rpy="0 0 0" xyz="0 0 0"/>
      <geometry>
        <box size="0.001 0.001 0.001"/>
        <!--the collision boundary for parts are taken into account by collision boundary of the base_link-->
      </geometry>
    </collision>
  </link>
  <gazebo reference="base_link_top_plate_part">
    <material>Gazebo/Yellow</material>
  </gazebo>
  <!-- User Rail -->
  <joint name="base_link_user_rail_joint" type="fixed">
    <origin rpy="0.0 0.0 0.0" xyz="0.272 0.0 0.245"/>
    <parent link="base_link"/>
    <child link="base_link_user_rail_part"/>
  </joint>
  <link name="base_link_user_rail_part">
    <inertial>
      <mass value="0.1"/>
      <origin xyz="0.0 0.0 0.0"/>
      <inertia ixx="0.01" ixy="0.0" ixz="0.0" iyy="0.01" iyz="0.0" izz="0.01"/>
    </inertial>
    <visual>
      <origin rpy="0 0 0" xyz="0 0 0"/>
      <geometry>
        <mesh filename="package://husky_description/Media/models/user_rail.stl"/>
      </geometry>
      <material name="DarkGray"/>
    </visual>
    <collision>
      <origin rpy="0 0 0" xyz="0 0 0"/>
      <geometry>
        <box size="0.001 0.001 0.001"/>
        <!--the collision boundary for parts are taken into account by collision boundary of the base_link-->
      </geometry>
    </collision>
  </link>
  <gazebo reference="base_link_user_rail_part">
    <material>Gazebo/Grey</material>
  </gazebo>
  <!-- Bumpers -->
  <joint name="base_link_front_bumper_joint" type="fixed">
    <origin rpy="0.0 0.0 0.0" xyz="0.49 0.0 0.091"/>
    <parent link="base_link"/>
    <child link="base_link_front_bumper_part"/>
  </joint>
  <link name="base_link_front_bumper_part">
    <inertial>
      <mass value="0.1"/>
      <origin xyz="0.0 0.0 0.0"/>
      <inertia ixx="0.01" ixy="0.0" ixz="0.0" iyy="0.01" iyz="0.0" izz="0.01"/>
    </inertial>
    <visual>
      <origin rpy="0 0 0" xyz="0 0 0"/>
      <geometry>
        <mesh filename="package://husky_description/Media/models/bumper.stl"/>
      </geometry>
      <material name="DarkGray"/>
    </visual>
    <collision>
      <origin rpy="0 0 0" xyz="0 0 0"/>
      <geometry>
        <box size="0.001 0.001 0.001"/>
        <!--the collision boundary for parts are taken into account by collision boundary of the base_link-->
      </geometry>
    </collision>
  </link>
  <gazebo reference="base_link_front_bumper_part">
    <material>Gazebo/FlatBlack</material>
  </gazebo>
  <joint name="base_link_rear_bumper_joint" type="fixed">
    <origin rpy="0.0 0.0 3.14" xyz="-0.48 0.0 0.091"/>
    <parent link="base_link"/>
    <child link="base_link_rear_bumper_part"/>
  </joint>
  <link name="base_link_rear_bumper_part">
    <inertial>
      <mass value="0.1"/>
      <origin xyz="0.0 0.0 0.0"/>
      <inertia ixx="0.01" ixy="0.0" ixz="0.0" iyy="0.01" iyz="0.0" izz="0.01"/>
    </inertial>
    <visual>
      <origin rpy="0 0 0" xyz="0 0 0"/>
      <geometry>
        <mesh filename="package://husky_description/Media/models/bumper.stl"/>
      </geometry>
      <material name="DarkGray"/>
    </visual>
    <collision>
      <origin rpy="0 0 0" xyz="0 0 0"/>
      <geometry>
        <box size="0.001 0.001 0.001"/>
        <!--the collision boundary for parts are taken into account by collision boundary of the base_link-->
      </geometry>
    </collision>
  </link>
  <gazebo reference="base_link_rear_bumper_part">
    <material>Gazebo/FlatBlack</material>
  </gazebo>
  <gazebo>
    <controller:husky_plugin name="husky_diff_controller" plugin="libhusky_description.so">
      <alwaysOn>true</alwaysOn>
      <updateRate>100.0</updateRate>
      <backLeftJoint>joint_back_left_wheel</backLeftJoint>
      <backRightJoint>joint_back_right_wheel</backRightJoint>
      <frontLeftJoint>joint_front_left_wheel</frontLeftJoint>
      <frontRightJoint>joint_front_right_wheel</frontRightJoint>
      <wheelSeparation>0.5709</wheelSeparation>
      <wheelDiameter>0.3555</wheelDiameter>
      <torque>35</torque>
    </controller:husky_plugin>
  </gazebo>
  <!-- Ben ADDed -->
  <!-- Note: calibraton needs to be done to determine the offsets -->
  <!-- Front camera -->
  <joint name="bot_stereo/left_frame_joint" type="fixed">
    <origin rpy="0 0 0" xyz="0.0 0.04 0.04"/>
    <parent link="base_link_user_rail_part"/>
    <child link="bot_stereo/left_frame"/>
  </joint>
  <link name="bot_stereo/left_frame">
    <visual>
      <origin rpy="0 0 0" xyz="0.0 0.0 0"/>
      <geometry>
        <mesh filename="package://AERO_description/meshes/Manta-Camera-Lense.STL"/>
      </geometry>
    </visual>
    <inertial>
      <mass value="0.01"/>
      <origin rpy="0 0 0" xyz="0 0 0"/>
      <inertia ixx="0.001" ixy="0.0" ixz="0.0" iyy="0.001" iyz="0.0" izz="0.001"/>
    </inertial>
    <collision>
      <origin rpy="0 0 0" xyz="0 0 0"/>
      <geometry>
        <mesh filename="package://AERO_description/meshes/Manta-Camera-Lense.STL"/>
      </geometry>
    </collision>
  </link>
  <joint name="bot_stereo/left_optical_frame_joint" type="fixed">
    <origin rpy="-1.57079632679 0 -1.57079632679" xyz="0 0 0"/>
    <parent link="bot_stereo/left_frame"/>
    <child link="bot_stereo/left_optical_frame"/>
  </joint>
  <link name="bot_stereo/left_optical_frame">
    <inertial>
      <mass value="0.01"/>
      <origin rpy="0 0 0" xyz="0 0 0"/>
      <inertia ixx="0.001" ixy="0.0" ixz="0.0" iyy="0.001" iyz="0.0" izz="0.001"/>
    </inertial>
  </link>
  <gazebo reference="bot_stereo/left_frame">
    <sensor:camera name="bot_stereo/left_sensor">
      <imageFormat>R8G8B8</imageFormat>
      <imageSize>1292 734</imageSize>
      <hfov>50</hfov>
      <nearClip>0.1</nearClip>
      <farClip>100</farClip>
      <updateRate>40.0</updateRate>
      <visualize>true</visualize>
      <controller:gazebo_ros_prosilica name="bot_stereo/left_controller" plugin="libgazebo_ros_prosilica.so">
        <alwaysOn>true</alwaysOn>
        <updateRate>40.0</updateRate>
        <cameraName>l_camera</cameraName>
        <imageTopicName>image_raw</imageTopicName>
        <cameraInfoTopicName>camera_info</cameraInfoTopicName>
        <pollServiceName>request_image</pollServiceName>
        <frameName>bot_stereo/left_optical_frame</frameName>
        <CxPrime>646</CxPrime>
        <Cx>646</Cx>
        <Cy>367</Cy>
        <focalLength>1385.350816</focalLength>
        <!-- image_width / (2*tan(hfov_radian /2)) -->
        <distortionK1>0.0</distortionK1>
        <distortionK2>0.0</distortionK2>
        <distortionK3>0.0</distortionK3>
        <distortionT1>0.0</distortionT1>
        <distortionT2>0.0</distortionT2>
      </controller:gazebo_ros_prosilica>
    </sensor:camera>
    <material value="Gazebo/Red"/>
  </gazebo>
  <joint name="bot_stereo/right_frame_joint" type="fixed">
    <origin rpy="0 0 0" xyz="0.0 -0.04 0.04"/>
    <parent link="base_link_user_rail_part"/>
    <child link="bot_stereo/right_frame"/>
  </joint>
  <link name="bot_stereo/right_frame">
    <visual>
      <origin rpy="0 0 0" xyz="0.0 0.0 0"/>
      <geometry>
        <mesh filename="package://AERO_description/meshes/Manta-Camera-Lense.STL"/>
      </geometry>
    </visual>
    <inertial>
      <mass value="0.01"/>
      <origin rpy="0 0 0" xyz="0 0 0"/>
      <inertia ixx="0.001" ixy="0.0" ixz="0.0" iyy="0.001" iyz="0.0" izz="0.001"/>
    </inertial>
    <collision>
      <origin rpy="0 0 0" xyz="0 0 0"/>
      <geometry>
        <mesh filename="package://AERO_description/meshes/Manta-Camera-Lense.STL"/>
      </geometry>
    </collision>
  </link>
  <joint name="bot_stereo/right_optical_frame_joint" type="fixed">
    <origin rpy="-1.57079632679 0 -1.57079632679" xyz="0 0 0"/>
    <parent link="bot_stereo/right_frame"/>
    <child link="bot_stereo/right_optical_frame"/>
  </joint>
  <link name="bot_stereo/right_optical_frame">
    <inertial>
      <mass value="0.01"/>
      <origin rpy="0 0 0" xyz="0 0 0"/>
      <inertia ixx="0.001" ixy="0.0" ixz="0.0" iyy="0.001" iyz="0.0" izz="0.001"/>
    </inertial>
  </link>
  <gazebo reference="bot_stereo/right_frame">
    <sensor:camera name="bot_stereo/right_sensor">
      <imageFormat>R8G8B8</imageFormat>
      <imageSize>1292 734</imageSize>
      <hfov>50</hfov>
      <nearClip>0.1</nearClip>
      <farClip>100</farClip>
      <updateRate>40.0</updateRate>
      <visualize>true</visualize>
      <controller:gazebo_ros_prosilica name="bot_stereo/right_controller" plugin="libgazebo_ros_prosilica.so">
        <alwaysOn>true</alwaysOn>
        <updateRate>40.0</updateRate>
        <cameraName>r_camera</cameraName>
        <imageTopicName>image_raw</imageTopicName>
        <cameraInfoTopicName>camera_info</cameraInfoTopicName>
        <pollServiceName>request_image</pollServiceName>
        <frameName>bot_stereo/right_optical_frame</frameName>
        <CxPrime>646</CxPrime>
        <Cx>646</Cx>
        <Cy>367</Cy>
        <focalLength>1385.350816</focalLength>
        <!-- image_width / (2*tan(hfov_radian /2)) -->
        <distortionK1>0.0</distortionK1>
        <distortionK2>0.0</distortionK2>
        <distortionK3>0.0</distortionK3>
        <distortionT1>0.0</distortionT1>
        <distortionT2>0.0</distortionT2>
      </controller:gazebo_ros_prosilica>
    </sensor:camera>
    <material value="Gazebo/Red"/>
  </gazebo>
  <gazebo reference="r_camera_frame">
    <material>Gazebo/Red</material>
  </gazebo>
  <joint name="down_camera_frame_joint" type="fixed">
    <origin rpy="0 1.57079632679 0" xyz="-0.05 0 -0.05"/>
    <parent link="base_link_front_bumper_part"/>
    <child link="down_camera_frame"/>
  </joint>
  <link name="down_camera_frame">
    <visual>
      <origin rpy="0 0 0" xyz="0.0 0.0 0"/>
      <geometry>
        <mesh filename="package://AERO_description/meshes/Manta-Camera-Lense.STL"/>
      </geometry>
    </visual>
    <inertial>
      <mass value="0.01"/>
      <origin rpy="0 0 0" xyz="0 0 0"/>
      <inertia ixx="0.001" ixy="0.0" ixz="0.0" iyy="0.001" iyz="0.0" izz="0.001"/>
    </inertial>
    <collision>
      <origin rpy="0 0 0" xyz="0 0 0"/>
      <geometry>
        <mesh filename="package://AERO_description/meshes/Manta-Camera-Lense.STL"/>
      </geometry>
    </collision>
  </link>
  <joint name="down_camera_optical_frame_joint" type="fixed">
    <origin rpy="-1.57079632679 0 -1.57079632679" xyz="0 0 0"/>
    <parent link="down_camera_frame"/>
    <child link="down_camera_optical_frame"/>
  </joint>
  <link name="down_camera_optical_frame">
    <inertial>
      <mass value="0.01"/>
      <origin rpy="0 0 0" xyz="0 0 0"/>
      <inertia ixx="0.001" ixy="0.0" ixz="0.0" iyy="0.001" iyz="0.0" izz="0.001"/>
    </inertial>
  </link>
  <gazebo reference="down_camera_frame">
    <sensor:camera name="down_camera_sensor">
      <imageFormat>R8G8B8</imageFormat>
      <imageSize>1292 734</imageSize>
      <hfov>50</hfov>
      <nearClip>0.1</nearClip>
      <farClip>100</farClip>
      <updateRate>40.0</updateRate>
      <visualize>true</visualize>
      <controller:gazebo_ros_prosilica name="down_camera_controller" plugin="libgazebo_ros_prosilica.so">
        <alwaysOn>true</alwaysOn>
        <updateRate>40.0</updateRate>
        <cameraName>down_camera</cameraName>
        <imageTopicName>image_raw</imageTopicName>
        <cameraInfoTopicName>camera_info</cameraInfoTopicName>
        <pollServiceName>request_image</pollServiceName>
        <frameName>down_camera_optical_frame</frameName>
        <CxPrime>646</CxPrime>
        <Cx>646</Cx>
        <Cy>367</Cy>
        <focalLength>1385.350816</focalLength>
        <!-- image_width / (2*tan(hfov_radian /2)) -->
        <distortionK1>0.0</distortionK1>
        <distortionK2>0.0</distortionK2>
        <distortionK3>0.0</distortionK3>
        <distortionT1>0.0</distortionT1>
        <distortionT2>0.0</distortionT2>
      </controller:gazebo_ros_prosilica>
    </sensor:camera>
    <material value="Gazebo/Red"/>
  </gazebo>
  <gazebo reference="down_camera_frame">
    <material>Gazebo/Red</material>
  </gazebo>
  <!-- Laser -->
  <joint name="lms151_laser_joint" type="fixed">
    <axis xyz="0 1 0"/>
    <origin rpy="0 0 0" xyz="-0.05 0 0.05"/>
    <parent link="base_link_front_bumper_part"/>
    <child link="lms151_laser_link"/>
  </joint>
  <link name="lms151_laser_link" type="laser">
    <inertial>
      <mass value="0.001"/>
      <origin rpy="0 0 0" xyz="0 0 0"/>
      <inertia ixx="0.0001" ixy="0" ixz="0" iyy="0.000001" iyz="0" izz="0.0001"/>
    </inertial>
    <visual>
      <origin rpy="0 0 0" xyz="0.0 0.0 0"/>
      <geometry>
        <mesh filename="package://AERO_description/meshes/LMS151.STL"/>
      </geometry>
    </visual>
    <collision>
      <origin rpy="0 0 0" xyz="0 0 0"/>
      <geometry>
        <mesh filename="package://AERO_description/meshes/LMS151.STL"/>
      </geometry>
    </collision>
  </link>
  <gazebo reference="lms151_laser_link">
    <sensor:ray name="lms151_laser">
      <rayCount>640</rayCount>
      <rangeCount>640</rangeCount>
      <laserCount>1</laserCount>
      <visualize>true</visualize>
      <origin>0.0 0.0 0.0</origin>
      <displayRays>true</displayRays>
      <minAngle>-135</minAngle>
      <maxAngle>135</maxAngle>
      <minRange>0.5</minRange>
      <maxRange>50.0</maxRange>
      <!-- should resRange be in radians or degrees??? -->
      <resRange>14.3239448783</resRange>
      <updateRate>25</updateRate>
      <controller:gazebo_ros_laser name="gazebo_ros_lms151_laser_controller" plugin="libgazebo_ros_laser.so">
        <gaussianNoise>0.005</gaussianNoise>
        <alwaysOn>true</alwaysOn>
        <updateRate>25</updateRate>
        <topicName>front_laser</topicName>
        <frameName>lms151_laser_link</frameName>
        <interface:laser name="gazebo_ros_lms151_laser_iface"/>
      </controller:gazebo_ros_laser>
    </sensor:ray>
  </gazebo>
  <gazebo reference="lms151_laser_link">
    <material>Gazebo/White</material>
  </gazebo>
  <!-- Kinova Arm -->
  <joint name="arm_fixture" type="fixed">
    <origin rpy="0 0 0" xyz="0.0 -0.12 0.0"/>
    <parent link="base_link_top_plate_part"/>
    <child link="arm_base_link"/>
  </joint>
  <link name="arm_base_link">
    <inertial>
      <origin rpy="0 0 0" xyz="0 0 0"/>
      <mass value="0"/>
      <inertia ixx="0" ixy="0" ixz="0" iyy="0" iyz="0" izz="0"/>
    </inertial>
    <visual>
      <origin rpy="0 0 0" xyz="0 0 0"/>
      <geometry>
        <mesh filename="package://AERO_arm/meshes/base_link.STL"/>
      </geometry>
      <material name="">
        <color rgba="0.792156862745098 0.819607843137255 0.933333333333333 1"/>
      </material>
    </visual>
    <collision>
      <origin rpy="0 0 0" xyz="0 0 0"/>
      <geometry>
        <mesh filename="package://AERO_arm/meshes/base_link.STL"/>
      </geometry>
    </collision>
  </link>
  <link name="arm_Link1">
    <inertial>
      <origin rpy="0 0 0" xyz="0 0 0"/>
      <mass value="0"/>
      <inertia ixx="0" ixy="0" ixz="0" iyy="0" iyz="0" izz="0"/>
    </inertial>
    <visual>
      <origin rpy="1.57 0 0" xyz="0 0 0"/>
      <geometry>
        <mesh filename="package://AERO_arm/meshes/Link1.STL"/>
      </geometry>
      <material name="">
        <color rgba="0.792156862745098 0.819607843137255 0.933333333333333 1"/>
      </material>
    </visual>
    <collision>
      <origin rpy="1.57 0 0" xyz="0 0 0"/>
      <geometry>
        <mesh filename="package://AERO_arm/meshes/Link1.STL"/>
      </geometry>
    </collision>
  </link>
  <joint name="arm_Joint1" type="continuous">
    <origin rpy="0 0 0" xyz="0 0 0"/>
    <parent link="arm_base_link"/>
    <child link="arm_Link1"/>
    <axis xyz="0 0 -1"/>
  </joint>
  <link name="arm_Link2">
    <inertial>
      <origin rpy="0 0 0" xyz="0 0 0"/>
      <mass value="0"/>
      <inertia ixx="0" ixy="0" ixz="0" iyy="0" iyz="0" izz="0"/>
    </inertial>
    <visual>
      <origin rpy="3.14 0 0" xyz=".205 0 0"/>
      <geometry>
        <mesh filename="package://AERO_arm/meshes/Link2.STL"/>
      </geometry>
      <material name="">
        <color rgba="0.792156862745098 0.819607843137255 0.933333333333333 1"/>
      </material>
    </visual>
    <collision>
      <origin rpy="3.14 0 0" xyz=".205 0 0"/>
      <geometry>
        <mesh filename="package://AERO_arm/meshes/Link2.STL"/>
      </geometry>
    </collision>
  </link>
  <joint name="arm_Joint2" type="continuous">
    <!-- <origin
      xyz="0 0 0.11875"
      rpy="0.0025506 -1.5708 0" /> -->
    <origin rpy="0.0 -1.5708 0" xyz="0 0 0.12"/>
    <parent link="arm_Link1"/>
    <child link="arm_Link2"/>
    <axis xyz="0 0 -1"/>
  </joint>
  <link name="arm_Link3">
    <inertial>
      <!--
      <origin
        xyz="0.01 -.04125 0"
        rpy="0.01 0 0" />
-->
      <origin rpy="0.00 0 0" xyz="0.00 0 0"/>
      <mass value="0"/>
      <inertia ixx="0" ixy="0" ixz="0" iyy="0" iyz="0" izz="0"/>
    </inertial>
    <visual>
      <origin rpy="0 0 0" xyz="0 0 0"/>
      <geometry>
        <mesh filename="package://AERO_arm/meshes/Link4_origin.STL" scale="0.001 0.001 0.001"/>
      </geometry>
      <material name="">
        <color rgba="0.792156862745098 0.819607843137255 0.933333333333333 1"/>
      </material>
    </visual>
    <collision>
      <origin rpy="0 0 0" xyz="0 0 0"/>
      <geometry>
        <mesh filename="package://AERO_arm/meshes/Link4_origin.STL" scale="0.001 0.001 0.001"/>
      </geometry>
    </collision>
  </link>
  <joint name="arm_Joint3" type="continuous">
    <!--
    <origin
      xyz="0.40806 -0.038517 0"
      rpy="-3.1416 -7.9134E-09 -0.28747" />
-->
    <origin rpy="-3.1416 0 -0.28747" xyz="0.41 0 0"/>
    <parent link="arm_Link2"/>
    <child link="arm_Link3"/>
    <axis xyz="0 0 -1"/>
  </joint>
  <link name="arm_Link4">
    <inertial>
      <origin rpy="0 0 0" xyz="0 0 0"/>
      <mass value="0"/>
      <inertia ixx="0" ixy="0" ixz="0" iyy="0" iyz="0" izz="0"/>
    </inertial>
    <visual>
      <origin rpy="0 0 0" xyz="0 0 0"/>
      <geometry>
        <mesh filename="package://AERO_arm/meshes/origin_fixed.STL" scale="0.001 0.001 0.001"/>
      </geometry>
      <material name="">
        <color rgba="0.792156862745098 0.819607843137255 0.933333333333333 1"/>
      </material>
    </visual>
    <collision>
      <origin rpy="0 0 0" xyz="0 0 0"/>
      <geometry>
        <mesh filename="package://AERO_arm/meshes/origin_fixed.STL" scale="0.001 0.001 0.001"/>
      </geometry>
    </collision>
  </link>
  <joint name="arm_Joint4" type="continuous">
    <!--
    <origin
      xyz="0.12269 0.16673 0.011497"
      rpy="1.5708 0.064781 -0.63437" />
-->
    <origin rpy="0 -1.5708 0.0" xyz="0.2073 0.0 0.011497"/>
    <parent link="arm_Link3"/>
    <child link="arm_Link4"/>
    <axis xyz="0 0 1"/>
  </joint>
  <link name="arm_Link5">
    <inertial>
      <origin rpy="0 0 0" xyz="0 0 0"/>
      <mass value="0"/>
      <inertia ixx="0" ixy="0" ixz="0" iyy="0" iyz="0" izz="0"/>
    </inertial>
    <visual>
      <origin rpy="0 0 0" xyz="0 0 0"/>
      <geometry>
        <mesh filename="package://AERO_arm/meshes/origin_fixed.STL" scale="0.001 0.001 0.001"/>
      </geometry>
      <material name="">
        <color rgba="0.792156862745098 0.819607843137255 0.933333333333333 1"/>
      </material>
    </visual>
    <collision>
      <origin rpy="0 0 0" xyz="0 0 0"/>
      <geometry>
        <mesh filename="package://AERO_arm/meshes/origin_fixed.STL" scale="0.001 0.001 0.001"/>
      </geometry>
    </collision>
  </link>
  <joint name="arm_Joint5" type="continuous">
    <!--
    <origin
      xyz="0.030052 -0.016526 -0.065632"
      rpy="0.12154 -0.95472 -0.65131" />
-->
    <origin rpy="0.12154 -0.95472 -0.65131" xyz="0.027925 -0.019554 -0.065738"/>
    <parent link="arm_Link4"/>
    <child link="arm_Link5"/>
    <axis xyz="0 0 1"/>
  </joint>
  <link name="arm_Gripper">
    <inertial>
      <origin rpy="0 0 0" xyz="0 0 0"/>
      <mass value="0"/>
      <inertia ixx="0" ixy="0" ixz="0" iyy="0" iyz="0" izz="0"/>
    </inertial>
    <visual>
      <origin rpy="0 0 0" xyz="0 0 0"/>
      <geometry>
        <mesh filename="package://AERO_arm/meshes/Gripper_origin.STL" scale="0.001 0.001 0.001"/>
      </geometry>
      <material name="">
        <color rgba="0.792156862745098 0.819607843137255 0.933333333333333 1"/>
      </material>
    </visual>
    <collision>
      <origin rpy="0 0 0" xyz="0 0 0"/>
      <geometry>
        <mesh filename="package://AERO_arm/meshes/Gripper_origin.STL" scale="0.001 0.001 0.001"/>
      </geometry>
    </collision>
  </link>
  <joint name="arm_Joint6" type="continuous">
    <!--
    <origin
      xyz="-0.024641 -0.023854 -0.065632"
      rpy="-2.4455 0.72653 1.6683" />
    
-->
    <origin rpy="0.48869  2.1800 0" xyz="0.027925 -0.019554 -0.065738"/>
    <parent link="arm_Link5"/>
    <child link="arm_Gripper"/>
    <axis xyz="0 0 1"/>
  </joint>
</robot>

